Workbook

Sheet Financial Model
A1: Model Variables | H1: Month to Month Account Growth | I1: 1 | J1: 1 | K1: 1.5 | L1: 1.1 | M1: 1.15 | N1: 1.15 | O1: 1.2 | P1: 1.2 | Q1: 1.2 | R1: 1.3 | S1: 1.3 | T1: 1.3 | U1: 1.15 | V1: 1.15 | W1: 1.2 | X1: 1.2 | Y1: 1.15 | Z1: 1.15 | AA1: 1.15 | AB1: 1.15 | AC1: 1.15 | AD1: 1.15 | AE1: 1.15 | AF1: 1.15 | AG1: 1.15
A2: Average Cost Per Lead | C2: 15 | H2: Contract Account Growth | I2: 1 | J2: 2 | K2: 2 | L2: 0.6 | M2: 1.15 | N2: 1.15 | O2: 1.2 | P2: 1.2 | Q2: 1.2 | R2: 1.3 | S2: 1.3 | T2: 1.4 | U2: 1.15 | V2: 1.15 | W2: 1.15 | X2: 1.15 | Y2: 1.15 | Z2: 1.15 | AA2: 1.15 | AB2: 1.15 | AC2: 1.15 | AD2: 1.15 | AE2: 1.15 | AF2: 1.15 | AG2: 1.15
A3: Average Conversion Rate to Paid Account
A4: Attrition Rate | C4: 0.05
A5: Initial Month Attrition Rate | C5: 0.2 | I5: Jan
I6: Month 1 | J6: Month 2 | K6: Month 3 | L6: Month 4 | M6: Month 5 | N6: Month 6 | O6: Month 7 | P6: Month 8 | Q6: Month 9 | R6: Month 10 | S6: Month 11 | T6: Month 12 | U6: Month 13 | V6: Month 14 | W6: Month 15 | X6: Month 16 | Y6: Month 17 | Z6: Month 18 | AA6: Month 19 | AB6: Month 20 | AC6: Month 21 | AD6: Month 22 | AE6: Month 23 | AF6: Month 24 | AG6: Month 25
H7: Total Customer Count | I7: =I17+I20 -> 18 | J7: =J17+J20 -> 20.65 | K7: =K17+K20 -> 26.0175 | L7: =L17+L20 -> 29.366625 | M7: =M17+M20 -> 33.598294 | N7: =N17+N20 -> 38.473379 | O7: =O17+O20 -> 44.464873 | P7: =P17+P20 -> 51.739824 | ... AG7: =AG17+AG20 -> 929.00079
H8: Total Recurring Monthly Revenue | I8: =I27 -> 13800 | J8: =J27 -> 23765 | K8: =K27 -> 43386.242 | L8: =L27 -> 53119.271 | M8: =M27 -> 64621.847 | N8: =N27 -> 77564.822 | O8: =O27 -> 93090.439 | P8: =P27 -> 111621.66 | ... AG8: =AG27 -> 2225243.2
H9: Total Revenue Collected | I9: =SUM($I$27:I27) -> 13800 | J9: =SUM($J$27:J27) -> 23765 | K9: =SUM(K27:K27) -> 43386.242 | L9: =SUM(L27:L27) -> 53119.271 | M9: =SUM(M27:M27) -> 64621.847 | N9: =SUM(N27:N27) -> 77564.822 | O9: =SUM(O27:O27) -> 93090.439 | P9: =SUM(P27:P27) -> 111621.66 | Q9: =SUM(Q27:Q27) -> 133767.15 | R9: =SUM(R27:R27) -> 163383.17 | ... AG9: =SUM(AG27:AG27) -> 2225243.2
H10: COGS | I10: =I37 -> -13755.92 | J10: =J37 -> -13993.545 | K10: =K37 -> -16362.575 | L10: =L37 -> -17249.869 | M10: =M37 -> -18557.87 | N10: =N37 -> -20030.084 | O10: =O37 -> -22154.147 | P10: =P37 -> -24655.974 | ... AG10: =AG37 -> -253118.09
H11: OpEx | I11: =I61 -> -107642.67 | J11: =J61 -> -138676.39 | K11: =K61 -> -149936.27 | L11: =L61 -> -150636.3 | M11: =M61 -> -155566.8 | N11: =N61 -> -230322.46 | O11: =O61 -> -273681.66 | P11: =P61 -> -330458.75 | ... AG11: =AG61 -> -973439.92
H12: Working Capital | I12: 0 | J12: =I14 -> -107598.59 | K12: =J14 -> -21503.518 | L12: =K14 -> 355583.88 | M12: =L14 -> 300816.98 | N12: =M14 -> 251314.16 | O12: =N14 -> 193526.44 | P12: =O14 -> 140781.07 | Q12: =P14 -> 97288.015 | ... AG12: =AF14 -> 3541856.4
H13: Capital Raise | J13: 215000 | K13: 500000 | L13: 60000 | M13: 60000 | N13: 115000 | O13: 150000 | P13: 200000 | Q13: 200000 | R13: 200000 | S13: =S91*-1 -> 200000 | T13: =T91*-1 -> 200000 | U13: =U91*-1 -> 200000 | V13: =V91*-1 -> 200000 | W13: =W91*-1 -> 200000 | X13: =X91*-1 -> 200000 | Y13: 0 | Z13: 0 | AA13: 0 | AB13: 0 | AC13: 0 | AD13: 0 | AE13: 0 | AF13: 0 | AG13: 0
A14: Current Cost Structure | E14: Cost Per Account Breakdown | H14: Inhouse Capital Requirement | I14: =SUM(I9:I13) -> -107598.59 | J14: =SUM(J9:J13) -> -21503.518 | K14: =SUM(K9:K13) -> 355583.88 | L14: =SUM(L9:L13) -> 300816.98 | M14: =SUM(M9:M13) -> 251314.16 | N14: =SUM(N9:N13) -> 193526.44 | O14: =SUM(O9:O13) -> 140781.07 | P14: =SUM(P9:P13) -> 97288.015 | ... AG14: =SUM(AG9:AG13) -> 4540541.6
H15: Total Creation Multiple
A16: Revenue Summary | E16: New Account Summary | H16: Revenue Summary | I16: 1 | J16: 2 | K16: 3 | L16: 4 | M16: 5 | N16: 6 | O16: 7 | P16: 8 | Q16: 9 | R16: 10 | S16: 11 | T16: 12 | U16: 13 | V16: 14 | W16: 15 | X16: 16 | Y16: 17 | Z16: 18 | AA16: 19 | AB16: 20 | AC16: 21 | AD16: 22 | AE16: 23 | AF16: 24 | AG16: 25
A17: Total Accounts | C17: 15 | E17: Total Accounts | F17: 100 | H17: Total Accounts | I17: =C17 -> 15 | J17: =(I17-(I17*$C$4))+(I20-(I20*$C$5)) -> 16.65 | K17: =(J17-(J17*$C$4))+(J20-(J20*$C$5)) -> 19.0175 | L17: =(K17-(K17*$C$4))+(K20-(K20*$C$5)) -> 23.666625 | M17: =(L17-(L17*$C$4))+(L20-(L20*$C$5)) -> 27.043294 | N17: =(M17-(M17*$C$4))+(M20-(M20*$C$5)) -> 30.935129 | O17: =(N17-(N17*$C$4))+(N20-(N20*$C$5)) -> 35.418973 | P17: =(O17-(O17*$C$4))+(O20-(O20*$C$5)) -> 40.884744 | Q17: =(P17-(P17*$C$4))+(P20-(P20*$C$5)) -> 47.524571 | ... AG17: =(AF17-(AF17*$C$4))+(AF20-(AF20*$C$5)) -> 738.15792
A18: Montly Accounts Sold | C18: 2 | E18: Montly Accounts Sold | F18: 20 | H18: Montly Accounts Sold | I18: =I1*2 -> 2 | J18: =J1*I18 -> 2 | K18: =K1*J18 -> 3 | L18: =L1*K18 -> 3.3 | M18: =M1*L18 -> 3.795 | N18: =N1*M18 -> 4.36425 | O18: =O1*N18 -> 5.2371 | P18: =P1*O18 -> 6.28452 | Q18: =Q1*P18 -> 7.541424 | ... AG18: =AG1*AF18 -> 110.99979
A19: Contract Account Sold | C19: 1 | E19: Contract Account Sold | F19: 4 | H19: Contract Account Sold | I19: =I2*1 -> 1 | J19: =I19*J2 -> 2 | K19: =J19*K2 -> 4 | L19: =K19*L2 -> 2.4 | M19: =L19*M2 -> 2.76 | N19: =M19*N2 -> 3.174 | O19: =N19*O2 -> 3.8088 | P19: =O19*P2 -> 4.57056 | Q19: =P19*Q2 -> 5.484672 | ... AG19: =AF19*AG2 -> 79.843088
A20: Total Paid Accounts Onboarded | C20: 1 | E20: Total Paid Accounts Onboarded | F20: =SUM(F18:F19) -> 24 | H20: Total Paid Accounts Onboarded | I20: =SUM(I18:I19) -> 3 | J20: =SUM(J18:J19) -> 4 | K20: =SUM(K18:K19) -> 7 | L20: =SUM(L18:L19) -> 5.7 | M20: =SUM(M18:M19) -> 6.555 | N20: =SUM(N18:N19) -> 7.53825 | O20: =SUM(O18:O19) -> 9.0459 | P20: =SUM(P18:P19) -> 10.85508 | ... AG20: =SUM(AG18:AG19) -> 190.84288
A21: Average MMR | C21: 520 | E21: Average MMR | F21: 3500 | H21: Average MMR | I21: 520 | J21: =(I27/I7) -> 766.66667 | K21: =(J27/J7) -> 1150.8475 | L21: =(K27/K7) -> 1667.5792 | M21: =(L27/L7) -> 1808.8313 | N21: =(M27/M7) -> 1923.3669 | O21: =(N27/N7) -> 2016.0647 | P21: =(O27/O7) -> 2093.5726 | Q21: =(P27/P7) -> 2157.3646 | ... AG21: =(AF27/AF7) -> 2395.2678
A22: New Month-to-Month Average | C22: 500 | E22: New Month-to-Month Average | F22: 750 | H22: New Month-to-Month Average | I22: 500 | J22: 500 | K22: 500 | L22: 501 | M22: 502 | N22: 503 | O22: 504 | P22: 505 | Q22: 506 | R22: 507 | S22: 508 | T22: 509 | U22: 510 | V22: 511 | W22: 512 | X22: 513 | Y22: 514 | Z22: 515 | AA22: 516 | AB22: 517 | AC22: 518 | AD22: 519 | AE22: 520 | AF22: 521 | AG22: 522
A23: New Contract Average | C23: 7500 | E23: New Contract Average | F23: 6500 | H23: New Contract Average | I23: =5000 -> 5000 | J23: =5000 -> 5000 | K23: =5000 -> 5000 | L23: =5000 -> 5000 | M23: =5000 -> 5000 | N23: =5000 -> 5000 | O23: =5000 -> 5000 | P23: =5000 -> 5000 | ... AG23: =5000 -> 5000
A24: New Montly Account Revenue | C24: =(C23*C19)+(C18*C22) -> 8500 | E24: New Montly Account Revenue | F24: =(F23*F19)+(F18*F22) -> 41000 | H24: New Montly Account Revenue | I24: =(I23*I19)+(I18*I22) -> 6000 | J24: =(J23*J19)+(J18*J22) -> 11000 | K24: =K22*K18+(K23*K19) -> 21500 | L24: =L22*L18+(L23*L19) -> 13653.3 | M24: =M22*M18+(M23*M19) -> 15705.09 | N24: =N22*N18+(N23*N19) -> 18065.218 | O24: =O22*O18+(O23*O19) -> 21683.498 | P24: =P22*P18+(P23*P19) -> 26026.483 | Q24: =Q22*Q18+(Q23*Q19) -> 31239.321 | R24: =R22*R18+(R23*R19) -> 40620.921 | ... AG24: =AG22*AG18+(AG23*AG19) -> 457157.33
F25: =F23*F19+(F24*F20) -> 1010000
A26: New Account Revenue | C26: =SUM(C24:C25) -> 8500 | E26: New Account Revenue | H26: New Account Revenue | I26: =SUM(I24:I25) -> 6000 | J26: =SUM(J24:J25) -> 11000 | K26: =SUM(K24:K25) -> 21500 | L26: =SUM(L24:L25) -> 13653.3 | M26: =SUM(M24:M25) -> 15705.09 | N26: =SUM(N24:N25) -> 18065.218 | O26: =SUM(O24:O25) -> 21683.498 | P26: =SUM(P24:P25) -> 26026.483 | ... AG26: =SUM(AG24:AG25) -> 457157.33
A27: Total Monthly Revenue | C27: =C26+(C17*C21) -> 16300 | E27: Total Monthly Revenue | F27: =SUM(F25:F26) -> 1010000 | H27: Total Monthly Revenue | I27: =I26+I17*I21 -> 13800 | J27: =J26+(J17*J21) -> 23765 | K27: =K26+(K17*K21) -> 43386.242 | L27: =L26+(L17*L21) -> 53119.271 | M27: =M26+(M17*M21) -> 64621.847 | N27: =N26+(N17*N21) -> 77564.822 | O27: =O26+(O17*O21) -> 93090.439 | P27: =P26+(P17*P21) -> 111621.66 | Q27: =Q26+(Q17*Q21) -> 133767.15 | ... AG27: =AG26+(AG17*AG21) -> 2225243.2
A29: Gross Profit | C29: =C27+C37 -> 6415.67 | E29: Net Operating Income | H29: Gross Profit | I29: =I27+I37 -> 44.08 | J29: =J27+J37 -> 9771.4553 | K29: =K27+K37 -> 27023.666 | L29: =L27+L37 -> 35869.402 | M29: =M27+M37 -> 46063.977 | N29: =N27+N37 -> 57534.737 | O29: =O27+O37 -> 70936.292 | P29: =P27+P37 -> 86965.689 | ... AG29: =AG27+AG37 -> 1972125.1
A31: COGS | E31: COGS | H31: COGS
A32: Cloud Services | C32: -3162.95 | E32: Cloud Services | H32: Cloud Services | I32: =-3162.95*I65 -> -6325.9 | J32: =I32*J65 -> -6484.0475 | K32: =J32*K65 -> -6646.1487 | L32: =K32*L65 -> -6812.3024 | M32: =L32*M65 -> -6982.61 | N32: =M32*N65 -> -7157.1752 | O32: =N32*O65 -> -7336.1046 | P32: =O32*P65 -> -7519.5072 | Q32: =P32*Q65 -> -7707.4949 | ... AG32: =AF32*AG65 -> -11441.819
A33: Software - COGS | C33: -2093.47 | E33: Software - COGS | H33: Software - COGS | I33: -2093.47 | J33: =I33*J66 -> -2145.8067 | K33: =J33*K66 -> -2199.4519 | L33: =K33*L66 -> -2254.4382 | M33: =L33*M66 -> -2310.7992 | N33: =M33*N66 -> -2368.5692 | O33: =N33*O66 -> -2427.7834 | P33: =O33*P66 -> -2488.478 | Q33: =P33*Q66 -> -2550.6899 | ... AG33: =AF33*AG66 -> -3786.5135
A34: Software - Tools | C34: -1085.62 | E34: Software - Tools | H34: Software - Tools | I34: -1085.62 | J34: =I34*J67 -> -1112.7605 | K34: =J34*K67 -> -1140.5795 | L34: =K34*L67 -> -1169.094 | M34: =L34*M67 -> -1198.3214 | N34: =M34*N67 -> -1228.2794 | O34: =N34*O67 -> -1258.9864 | P34: =O34*P67 -> -1290.461 | Q34: =P34*Q67 -> -1322.7226 | ... AG34: =AF34*AG67 -> -1963.5891
A35: Voice AI Provider | C35: -708.64 | E35: Voice AI Provider | H35: Voice AI Provider | I35: =-708.64*I68 -> -1417.28 | J35: =I35*J68 -> -1417.28 | K35: =J35*K68 -> -2125.92 | L35: =K35*L68 -> -2338.512 | M35: =L35*M68 -> -2689.2888 | N35: =M35*N68 -> -3092.6821 | O35: =N35*O68 -> -3711.2185 | P35: =O35*P68 -> -4453.4623 | Q35: =P35*Q68 -> -5344.1547 | ... AG35: =AF35*AG68 -> -78658.89
A36: Telephony Carriers | C36: -2833.65 | E36: Telephony Carriers | H36: Telephony Carriers | I36: -2833.65 | J36: =I36*J69 -> -2833.65 | K36: =J36*K69 -> -4250.475 | L36: =K36*L69 -> -4675.5225 | M36: =L36*M69 -> -5376.8509 | N36: =M36*N69 -> -6183.3785 | O36: =N36*O69 -> -7420.0542 | P36: =O36*P69 -> -8904.065 | Q36: =P36*Q69 -> -10684.878 | ... AG36: =AF36*AG69 -> -157267.28
A37: Total COGS | C37: =SUM(C32:C36) -> -9884.33 | D37: 0 | E37: Total COGS | F37: =C37/$C$20 -> -9884.33 | H37: Total COGS | I37: =SUM(I32:I36) -> -13755.92 | J37: =SUM(J32:J36) -> -13993.545 | K37: =SUM(K32:K36) -> -16362.575 | L37: =SUM(L32:L36) -> -17249.869 | M37: =SUM(M32:M36) -> -18557.87 | N37: =SUM(N32:N36) -> -20030.084 | O37: =SUM(O32:O36) -> -22154.147 | P37: =SUM(P32:P36) -> -24655.974 | ... AG37: =SUM(AG32:AG36) -> -253118.09
A40: Operating Costs | E40: Operating Costs Per Sale | H40: Operating Costs
A41: Bank Service Charges | C41: -250 | D41: 1 | E41: Bank Service Charges | F41: =C41/$C$20 -> -250 | H41: Bank Service Charges | I41: =C41 -> -250 | J41: =I41*J72 -> -250 | K41: =J41*K72 -> -250 | L41: =K41*L72 -> -250 | M41: =L41*M72 -> -250 | N41: =M41*N72 -> -250 | O41: =N41*O72 -> -250 | P41: =O41*P72 -> -250 | Q41: =P41*Q72 -> -250 | ... AG41: =AF41*AG72 -> -250
A42: Total Dev Contract labor | C42: -53804.906 | D42: 1 | E42: Total Contract labor | F42: =C42/$C$20 -> -53804.906 | H42: Total Contract labor | I42: =$C$42*I73 -> -67256.133 | J42: =I42*J73 -> -70618.94 | K42: =J42*K73 -> -74149.887 | L42: =K42*L73 -> -77857.381 | M42: =L42*M73 -> -85643.119 | N42: =M42*N73 -> -94207.431 | O42: =N42*O73 -> -103628.17 | P42: =O42*P73 -> -113990.99 | Q42: =P42*Q73 -> -119690.54 | ... AG42: =AF42*AG73 -> -181798.48
A43: Lincense and Subscription Fees | C43: -121.36364 | D43: 1 | E43: Lincense and Subscription Fees | F43: =C43/$C$20 -> -121.36364 | H43: Lincense and Subscription Fees | I43: =C43 -> -121.36364 | J43: =I43*J74 -> -124.39773 | K43: =J43*K74 -> -127.50767 | L43: =K43*L74 -> -130.69536 | M43: =L43*M74 -> -133.96275 | N43: =M43*N74 -> -137.31181 | O43: =N43*O74 -> -140.74461 | P43: =O43*P74 -> -144.26323 | Q43: =P43*Q74 -> -147.86981 | ... AG43: =AF43*AG74 -> -219.51356
A44: Software & apps | C44: -4477.18 | E44: Software & apps | H44: Software & apps | I44: =C44 -> -4477.18 | J44: =I44*J75 -> -4589.1095 | K44: =J44*K75 -> -4703.8372 | L44: =K44*L75 -> -4821.4332 | M44: =L44*M75 -> -4941.969 | N44: =M44*N75 -> -5065.5182 | O44: =N44*O75 -> -5192.1562 | P44: =O44*P75 -> -5321.9601 | Q44: =P44*Q75 -> -5455.0091 | ... AG44: =AF44*AG75 -> -8097.9916
...

Sheet Current Payroll
B2: Full Monthly Payroll | C2: country
A3: Kyle Nadauld | B3: 5200 | C3: US
A4: Daniel McConnell | B4: 3000 | C4: US
A5: Jonathan Gibby | B5: 7000.13 | C5: US
A6: Tyler (TK) Karren | B6: 5200 | C6: US
A9: Nikola Knežević | B9: 10400 | C9: SERB
A10: Sebastian | B10: 8666.67 | C10: SERB
A11: Nebojsa Krstovic | B11: 3813.33 | C11: SERB
A12: QA Marco | B12: 3466.67 | C12: SERB
A13: Iva Lukac | B13: 1733.33 | C13: SERB
A14: Todor Mihajlovic | B14: 8666.67 | C14: SERB
A17: Gabriel Ceniza | B17: 2894.74
A18: Jenriel Jadraque | B18: 2368.42
A19: Ariel Manayon | B19: 4200
B20: =SUM(B3:B19) -> 66609.96

Sheet Growth Analysis
A1: month | B1: phase | C1: mrr | D1: arr | E1: momGrowth | F1: customers | G1: netNewCustomers | H1: churnRate | I1: arpu | J1: cac | K1: ltv | L1: ltvCacRatio | M1: grossMargin | N1: netBurn | O1: burnMultiple | P1: rule40Score | Q1: cogs | R1: burn | S1: expansionRevenue | T1: netRevenueRetention
A2: 1 | B2: Phase 1 | C2: 22770 | D2: 273240 | E2: 0.15 | F2: 24 | G2: 2 | H2: 0.05 | I2: 949 | J2: 15115 | K2: 227700 | L2: 15.1x | M2: 0.6 | N2: 90594 | O2: 30.5 | P2: 75 | Q2: 9108 | R2: 113364 | S2: 1584 | T2: 1.03 | W2: =R2/O2 -> 3716.8525
A3: 2 | B3: Phase 1 | C3: 26185 | D3: 314226 | E3: 0.15 | F3: 27 | G3: 3 | H3: 0.05 | I3: 970 | J3: 15115 | K3: 232760 | L3: 15.4x | M3: 0.6 | N3: 87179 | O3: 25.52 | P3: 75 | Q3: 10474 | R3: 113364 | S3: 1822 | T3: 1.03
A4: 3 | B4: Phase 1 | C4: 30113 | D4: 361360 | E4: 0.15 | F4: 31 | G4: 4 | H4: 0.05 | I4: 971 | J4: 11336 | K4: 233135 | L4: 20.6x | M4: 0.6 | N4: 83251 | O4: 21.2 | P4: 75 | Q4: 12045 | R4: 113364 | S4: 2095 | T4: 1.03
A5: 4 | B5: Phase 1 | C5: 34630 | D5: 415564 | E5: 0.15 | F5: 35 | G5: 4 | H5: 0.05 | I5: 989 | J5: 11336 | K5: 237465 | L5: 20.9x | M5: 0.6 | N5: 78734 | O5: 17.43 | P5: 75 | Q5: 13852 | R5: 113364 | S5: 2409 | T5: 1.03
A6: 5 | B6: Phase 1 | C6: 39825 | D6: 477898 | E6: 0.15 | F6: 40 | G6: 5 | H6: 0.05 | I6: 996 | J6: 9069 | K6: 238949 | L6: 26.3x | M6: 0.6 | N6: 73539 | O6: 14.16 | P6: 75 | Q6: 15930 | R6: 113364 | S6: 2770 | T6: 1.03
A7: 6 | B7: Phase 1 | C7: 45799 | D7: 549583 | E7: 0.15 | F7: 46 | G7: 6 | H7: 0.05 | I7: 996 | J7: 7558 | K7: 238949 | L7: 31.6x | M7: 0.6 | N7: 67566 | O7: 11.31 | P7: 75 | Q7: 18319 | R7: 113364 | S7: 3186 | T7: 1.03
A8: 7 | B8: Phase 1 | C8: 52668 | D8: 632021 | E8: 0.15 | F8: 52 | G8: 6 | H8: 0.05 | I8: 1013 | J8: 7558 | K8: 243085 | L8: 32.2x | M8: 0.6 | N8: 60696 | O8: 8.84 | P8: 75 | Q8: 21067 | R8: 113364 | S8: 3664 | T8: 1.03
A9: 8 | B9: Phase 1 | C9: 60569 | D9: 726824 | E9: 0.15 | F9: 59 | G9: 7 | H9: 0.05 | I9: 1027 | J9: 6478 | K9: 246381 | L9: 38.0x | M9: 0.6 | N9: 52796 | O9: 6.68 | P9: 75 | Q9: 24227 | R9: 113364 | S9: 4213 | T9: 1.03
A10: 9 | B10: Phase 1 | C10: 69654 | D10: 835847 | E10: 0.15 | F10: 67 | G10: 8 | H10: 0.05 | I10: 1040 | J10: 5668 | K10: 249507 | L10: 44.0x | M10: 0.6 | N10: 43710 | O10: 4.81 | P10: 75 | Q10: 27862 | R10: 113364 | S10: 4845 | T10: 1.03
A11: 10 | B11: Phase 1 | C11: 80102 | D11: 961225 | E11: 0.15 | F11: 77 | G11: 10 | H11: 0.05 | I11: 1040 | J11: 4535 | K11: 249669 | L11: 55.1x | M11: 0.6 | N11: 33262 | O11: 3.18 | P11: 75 | Q11: 32041 | R11: 113364 | S11: 5572 | T11: 1.03
A12: 11 | B12: Phase 1 | C12: 92117 | D12: 1105408 | E12: 0.15 | F12: 88 | G12: 11 | H12: 0.05 | I12: 1047 | J12: 4122 | K12: 251229 | L12: 60.9x | M12: 0.6 | N12: 21247 | O12: 1.77 | P12: 75 | Q12: 36847 | R12: 113364 | S12: 6408 | T12: 1.03
A13: 12 | B13: Phase 1 | C13: 105935 | D13: 1271219 | E13: 0.15 | F13: 101 | G13: 13 | H13: 0.05 | I13: 1049 | J13: 3488 | K13: 251727 | L13: 72.2x | M13: 0.6 | N13: 7429 | O13: 0.54 | P13: 75 | Q13: 42374 | R13: 113364 | S13: 7369 | T13: 1.03
A14: 13 | B14: Phase 2 | C14: 121825 | D14: 1461902 | E14: 0.15 | F14: 116 | G14: 15 | H14: 0.05 | I14: 1050 | J14: 3023 | K14: 252052 | L14: 83.4x | M14: 0.6 | N14: -8461 | O14: -0.53 | P14: 75 | Q14: 48730 | R14: 113364 | S14: 8475 | T14: 1.03
... A37: 36 | B37: Phase 4 | C37: 3032407 | D37: 36388880 | E37: 0.15 | F37: 2799 | G37: 365 | H37: 0.05 | I37: 1083 | J37: 124 | K37: 260013 | L37: 2092.9x | M37: 0.6 | N37: -2919042 | O37: -7.38 | P37: 75 | Q37: 1212963 | R37: 113364 | S37: 210950 | T37: 1.03

Sheet Sheet2
A1: ='Financial Model'!H1 -> Month to Month Account Growth | B1: ='Financial Model'!I1 -> 1 | C1: ='Financial Model'!J1 -> 1 | D1: ='Financial Model'!K1 -> 1.5 | E1: ='Financial Model'!L1 -> 1.1 | F1: ='Financial Model'!M1 -> 1.15 | G1: ='Financial Model'!N1 -> 1.15 | H1: ='Financial Model'!O1 -> 1.2 | ... U1: ='Financial Model'!AB1 -> 1.15
A2: ='Financial Model'!H2 -> Contract Account Growth | B2: ='Financial Model'!I2 -> 1 | C2: ='Financial Model'!J2 -> 2 | D2: ='Financial Model'!K2 -> 2 | E2: ='Financial Model'!L2 -> 0.6 | F2: ='Financial Model'!M2 -> 1.15 | G2: ='Financial Model'!N2 -> 1.15 | H2: ='Financial Model'!O2 -> 1.2 | ... U2: ='Financial Model'!AB2 -> 1.15
A3: ='Financial Model'!H3 -> 0 | B3: ='Financial Model'!I3 -> 0 | C3: ='Financial Model'!J3 -> 0 | D3: ='Financial Model'!K3 -> 0 | E3: ='Financial Model'!L3 -> 0 | F3: ='Financial Model'!M3 -> 0 | G3: ='Financial Model'!N3 -> 0 | H3: ='Financial Model'!O3 -> 0 | ... U3: ='Financial Model'!AB3 -> 0
A4: ='Financial Model'!H4 -> 0 | B4: ='Financial Model'!I4 -> 0 | C4: ='Financial Model'!J4 -> 0 | D4: ='Financial Model'!K4 -> 0 | E4: ='Financial Model'!L4 -> 0 | F4: ='Financial Model'!M4 -> 0 | G4: ='Financial Model'!N4 -> 0 | H4: ='Financial Model'!O4 -> 0 | ... U4: ='Financial Model'!AB4 -> 0
A5: ='Financial Model'!H5 -> 0 | B5: ='Financial Model'!I5 -> Jan | C5: ='Financial Model'!J5 -> 0 | D5: ='Financial Model'!K5 -> 0 | E5: ='Financial Model'!L5 -> 0 | F5: ='Financial Model'!M5 -> 0 | G5: ='Financial Model'!N5 -> 0 | H5: ='Financial Model'!O5 -> 0 | ... U5: ='Financial Model'!AB5 -> 0
A6: ` | B6: ='Financial Model'!I6 -> Month 1 | C6: ='Financial Model'!J6 -> Month 2 | D6: ='Financial Model'!K6 -> Month 3 | E6: ='Financial Model'!L6 -> Month 4 | F6: ='Financial Model'!M6 -> Month 5 | G6: ='Financial Model'!N6 -> Month 6 | H6: ='Financial Model'!O6 -> Month 7 | I6: ='Financial Model'!P6 -> Month 8 | ... U6: ='Financial Model'!AB6 -> Month 20
A7: ='Financial Model'!H7 -> Total Customer Count | B7: ='Financial Model'!I7 -> 18 | C7: ='Financial Model'!J7 -> 20.65 | D7: ='Financial Model'!K7 -> 26.0175 | E7: ='Financial Model'!L7 -> 29.366625 | F7: ='Financial Model'!M7 -> 33.598294 | G7: ='Financial Model'!N7 -> 38.473379 | H7: ='Financial Model'!O7 -> 44.464873 | ... U7: ='Financial Model'!AB7 -> 441.82827
A8: ='Financial Model'!H8 -> Total Recurring Monthly Revenue | B8: ='Financial Model'!I8 -> 13800 | C8: ='Financial Model'!J8 -> 23765 | D8: ='Financial Model'!K8 -> 43386.242 | E8: ='Financial Model'!L8 -> 53119.271 | F8: ='Financial Model'!M8 -> 64621.847 | G8: ='Financial Model'!N8 -> 77564.822 | H8: ='Financial Model'!O8 -> 93090.439 | ... U8: ='Financial Model'!AB8 -> 1059050.8
A9: ='Financial Model'!H9 -> Total Revenue Collected | B9: ='Financial Model'!I9 -> 13800 | C9: ='Financial Model'!J9 -> 23765 | D9: ='Financial Model'!K9 -> 43386.242 | E9: ='Financial Model'!L9 -> 53119.271 | F9: ='Financial Model'!M9 -> 64621.847 | G9: ='Financial Model'!N9 -> 77564.822 | H9: ='Financial Model'!O9 -> 93090.439 | ... U9: ='Financial Model'!AB9 -> 1059050.8
A10: ='Financial Model'!H10 -> COGS | B10: ='Financial Model'!I10 -> -13755.92 | C10: ='Financial Model'!J10 -> -13993.545 | D10: ='Financial Model'!K10 -> -16362.575 | E10: ='Financial Model'!L10 -> -17249.869 | F10: ='Financial Model'!M10 -> -18557.87 | G10: ='Financial Model'!N10 -> -20030.084 | H10: ='Financial Model'!O10 -> -22154.147 | ... U10: ='Financial Model'!AB10 -> -132492.15
A11: ='Financial Model'!H12 -> Working Capital | B11: ='Financial Model'!I12 -> 0 | C11: ='Financial Model'!J12 -> -107598.59 | D11: ='Financial Model'!K12 -> -21503.518 | E11: ='Financial Model'!L12 -> 355583.88 | F11: ='Financial Model'!M12 -> 300816.98 | G11: ='Financial Model'!N12 -> 251314.16 | H11: ='Financial Model'!O12 -> 193526.44 | ... U11: ='Financial Model'!AB12 -> 885699.75
A12: ='Financial Model'!H13 -> Capital Raise | B12: ='Financial Model'!I13 -> 0 | C12: ='Financial Model'!J13 -> 215000 | D12: ='Financial Model'!K13 -> 500000 | E12: ='Financial Model'!L13 -> 60000 | F12: ='Financial Model'!M13 -> 60000 | G12: ='Financial Model'!N13 -> 115000 | H12: ='Financial Model'!O13 -> 150000 | ... U12: ='Financial Model'!AB13 -> 0
A13: ='Financial Model'!H14 -> Inhouse Capital Requirement | B13: ='Financial Model'!I14 -> -107598.59 | C13: ='Financial Model'!J14 -> -21503.518 | D13: ='Financial Model'!K14 -> 355583.88 | E13: ='Financial Model'!L14 -> 300816.98 | F13: ='Financial Model'!M14 -> 251314.16 | G13: ='Financial Model'!N14 -> 193526.44 | H13: ='Financial Model'!O14 -> 140781.07 | ... U13: ='Financial Model'!AB14 -> 1172974.4
A14: ='Financial Model'!H15 -> Total Creation Multiple | B14: ='Financial Model'!I15 -> 0 | C14: ='Financial Model'!J15 -> 0 | D14: ='Financial Model'!K15 -> 0 | E14: ='Financial Model'!L15 -> 0 | F14: ='Financial Model'!M15 -> 0 | G14: ='Financial Model'!N15 -> 0 | H14: ='Financial Model'!O15 -> 0 | ... U14: ='Financial Model'!AB15 -> 0
A15: ='Financial Model'!H16 -> Revenue Summary | B15: ='Financial Model'!I16 -> 1 | C15: ='Financial Model'!J16 -> 2 | D15: ='Financial Model'!K16 -> 3 | E15: ='Financial Model'!L16 -> 4 | F15: ='Financial Model'!M16 -> 5 | G15: ='Financial Model'!N16 -> 6 | H15: ='Financial Model'!O16 -> 7 | ... U15: ='Financial Model'!AB16 -> 20
A16: ='Financial Model'!H17 -> Total Accounts | B16: ='Financial Model'!I17 -> 15 | C16: ='Financial Model'!J17 -> 16.65 | D16: ='Financial Model'!K17 -> 19.0175 | E16: ='Financial Model'!L17 -> 23.666625 | F16: ='Financial Model'!M17 -> 27.043294 | G16: ='Financial Model'!N17 -> 30.935129 | H16: ='Financial Model'!O17 -> 35.418973 | ... U16: ='Financial Model'!AB17 -> 346.94563
A17: ='Financial Model'!H18 -> Montly Accounts Sold | B17: ='Financial Model'!I18 -> 2 | C17: ='Financial Model'!J18 -> 2 | D17: ='Financial Model'!K18 -> 3 | E17: ='Financial Model'!L18 -> 3.3 | F17: ='Financial Model'!M18 -> 3.795 | G17: ='Financial Model'!N18 -> 4.36425 | H17: ='Financial Model'!O18 -> 5.2371 | ... U17: ='Financial Model'!AB18 -> 55.186513
A18: ='Financial Model'!H19 -> Contract Account Sold | B18: ='Financial Model'!I19 -> 1 | C18: ='Financial Model'!J19 -> 2 | D18: ='Financial Model'!K19 -> 4 | E18: ='Financial Model'!L19 -> 2.4 | F18: ='Financial Model'!M19 -> 2.76 | G18: ='Financial Model'!N19 -> 3.174 | H18: ='Financial Model'!O19 -> 3.8088 | ... U18: ='Financial Model'!AB19 -> 39.696126
A19: ='Financial Model'!H20 -> Total Paid Accounts Onboarded | B19: ='Financial Model'!I20 -> 3 | C19: ='Financial Model'!J20 -> 4 | D19: ='Financial Model'!K20 -> 7 | E19: ='Financial Model'!L20 -> 5.7 | F19: ='Financial Model'!M20 -> 6.555 | G19: ='Financial Model'!N20 -> 7.53825 | H19: ='Financial Model'!O20 -> 9.0459 | ... U19: ='Financial Model'!AB20 -> 94.882638
A20: ='Financial Model'!H21 -> Average MMR | B20: ='Financial Model'!I21 -> 520 | C20: ='Financial Model'!J21 -> 766.66667 | D20: ='Financial Model'!K21 -> 1150.8475 | E20: ='Financial Model'!L21 -> 1667.5792 | F20: ='Financial Model'!M21 -> 1808.8313 | G20: ='Financial Model'!N21 -> 1923.3669 | H20: ='Financial Model'!O21 -> 2016.0647 | ... U20: ='Financial Model'!AB21 -> 2398.182
A21: ='Financial Model'!H22 -> New Month-to-Month Average | B21: ='Financial Model'!I22 -> 500 | C21: ='Financial Model'!J22 -> 500 | D21: ='Financial Model'!K22 -> 500 | E21: ='Financial Model'!L22 -> 501 | F21: ='Financial Model'!M22 -> 502 | G21: ='Financial Model'!N22 -> 503 | H21: ='Financial Model'!O22 -> 504 | ... U21: ='Financial Model'!AB22 -> 517
A22: ='Financial Model'!H23 -> New Contract Average | B22: ='Financial Model'!I23 -> 5000 | C22: ='Financial Model'!J23 -> 5000 | D22: ='Financial Model'!K23 -> 5000 | E22: ='Financial Model'!L23 -> 5000 | F22: ='Financial Model'!M23 -> 5000 | G22: ='Financial Model'!N23 -> 5000 | H22: ='Financial Model'!O23 -> 5000 | ... U22: ='Financial Model'!AB23 -> 5000
... A26: ='Financial Model'!H27 -> Total Monthly Revenue | B26: ='Financial Model'!I27 -> 13800 | C26: ='Financial Model'!J27 -> 23765 | D26: ='Financial Model'!K27 -> 43386.242 | E26: ='Financial Model'!L27 -> 53119.271 | F26: ='Financial Model'!M27 -> 64621.847 | G26: ='Financial Model'!N27 -> 77564.822 | H26: ='Financial Model'!O27 -> 93090.439 | ... U26: ='Financial Model'!AB27 -> 1059050.8
A27: ='Financial Model'!#REF! -> #REF! | B27: ='Financial Model'!#REF! -> #REF! | C27: ='Financial Model'!#REF! -> #REF! | D27: ='Financial Model'!#REF! -> #REF! | E27: ='Financial Model'!#REF! -> #REF! | F27: ='Financial Model'!#REF! -> #REF! | G27: ='Financial Model'!#REF! -> #REF! | H27: ='Financial Model'!#REF! -> #REF! | ... U27: ='Financial Model'!#REF! -> #REF!
A28: ='Financial Model'!H28 -> 0 | B28: ='Financial Model'!I28 -> 0 | C28: ='Financial Model'!J28 -> 0 | D28: ='Financial Model'!K28 -> 0 | E28: ='Financial Model'!L28 -> 0 | F28: ='Financial Model'!M28 -> 0 | G28: ='Financial Model'!N28 -> 0 | H28: ='Financial Model'!O28 -> 0 | ... U28: ='Financial Model'!AB28 -> 0
A29: ='Financial Model'!H29 -> Gross Profit | B29: ='Financial Model'!I29 -> 44.08 | C29: ='Financial Model'!J29 -> 9771.4553 | D29: ='Financial Model'!K29 -> 27023.666 | E29: ='Financial Model'!L29 -> 35869.402 | F29: ='Financial Model'!M29 -> 46063.977 | G29: ='Financial Model'!N29 -> 57534.737 | H29: ='Financial Model'!O29 -> 70936.292 | ... U29: ='Financial Model'!AB29 -> 926558.68
A30: ='Financial Model'!H30 -> 0 | B30: ='Financial Model'!I30 -> 0 | C30: ='Financial Model'!J30 -> 0 | D30: ='Financial Model'!K30 -> 0 | E30: ='Financial Model'!L30 -> 0 | F30: ='Financial Model'!M30 -> 0 | G30: ='Financial Model'!N30 -> 0 | H30: ='Financial Model'!O30 -> 0 | ... U30: ='Financial Model'!AB30 -> 0
A31: ='Financial Model'!H31 -> COGS | B31: ='Financial Model'!I31 -> 0 | C31: ='Financial Model'!J31 -> 0 | D31: ='Financial Model'!K31 -> 0 | E31: ='Financial Model'!L31 -> 0 | F31: ='Financial Model'!M31 -> 0 | G31: ='Financial Model'!N31 -> 0 | H31: ='Financial Model'!O31 -> 0 | ... U31: ='Financial Model'!AB31 -> 0
A32: ='Financial Model'!#REF! -> #REF! | B32: ='Financial Model'!#REF! -> #REF! | C32: ='Financial Model'!#REF! -> #REF! | D32: ='Financial Model'!#REF! -> #REF! | E32: ='Financial Model'!#REF! -> #REF! | F32: ='Financial Model'!#REF! -> #REF! | G32: ='Financial Model'!#REF! -> #REF! | H32: ='Financial Model'!#REF! -> #REF! | ... U32: ='Financial Model'!#REF! -> #REF!
A33: ='Financial Model'!#REF! -> #REF! | B33: ='Financial Model'!#REF! -> #REF! | C33: ='Financial Model'!#REF! -> #REF! | D33: ='Financial Model'!#REF! -> #REF! | E33: ='Financial Model'!#REF! -> #REF! | F33: ='Financial Model'!#REF! -> #REF! | G33: ='Financial Model'!#REF! -> #REF! | H33: ='Financial Model'!#REF! -> #REF! | ... U33: ='Financial Model'!#REF! -> #REF!
A34: ='Financial Model'!#REF! -> #REF! | B34: ='Financial Model'!#REF! -> #REF! | C34: ='Financial Model'!#REF! -> #REF! | D34: ='Financial Model'!#REF! -> #REF! | E34: ='Financial Model'!#REF! -> #REF! | F34: ='Financial Model'!#REF! -> #REF! | G34: ='Financial Model'!#REF! -> #REF! | H34: ='Financial Model'!#REF! -> #REF! | ... U34: ='Financial Model'!#REF! -> #REF!
A35: ='Financial Model'!#REF! -> #REF! | B35: ='Financial Model'!#REF! -> #REF! | C35: ='Financial Model'!#REF! -> #REF! | D35: ='Financial Model'!#REF! -> #REF! | E35: ='Financial Model'!#REF! -> #REF! | F35: ='Financial Model'!#REF! -> #REF! | G35: ='Financial Model'!#REF! -> #REF! | H35: ='Financial Model'!#REF! -> #REF! | ... U35: ='Financial Model'!#REF! -> #REF!
A36: ='Financial Model'!#REF! -> #REF! | B36: ='Financial Model'!#REF! -> #REF! | C36: ='Financial Model'!#REF! -> #REF! | D36: ='Financial Model'!#REF! -> #REF! | E36: ='Financial Model'!#REF! -> #REF! | F36: ='Financial Model'!#REF! -> #REF! | G36: ='Financial Model'!#REF! -> #REF! | H36: ='Financial Model'!#REF! -> #REF! | ... U36: ='Financial Model'!#REF! -> #REF!
A37: ='Financial Model'!#REF! -> #REF! | B37: ='Financial Model'!#REF! -> #REF! | C37: ='Financial Model'!#REF! -> #REF! | D37: ='Financial Model'!#REF! -> #REF! | E37: ='Financial Model'!#REF! -> #REF! | F37: ='Financial Model'!#REF! -> #REF! | G37: ='Financial Model'!#REF! -> #REF! | H37: ='Financial Model'!#REF! -> #REF! | ... U37: ='Financial Model'!#REF! -> #REF!
A38: ='Financial Model'!#REF! -> #REF! | B38: ='Financial Model'!#REF! -> #REF! | C38: ='Financial Model'!#REF! -> #REF! | D38: ='Financial Model'!#REF! -> #REF! | E38: ='Financial Model'!#REF! -> #REF! | F38: ='Financial Model'!#REF! -> #REF! | G38: ='Financial Model'!#REF! -> #REF! | H38: ='Financial Model'!#REF! -> #REF! | ... U38: ='Financial Model'!#REF! -> #REF!
A39: ='Financial Model'!#REF! -> #REF! | B39: ='Financial Model'!#REF! -> #REF! | C39: ='Financial Model'!#REF! -> #REF! | D39: ='Financial Model'!#REF! -> #REF! | E39: ='Financial Model'!#REF! -> #REF! | F39: ='Financial Model'!#REF! -> #REF! | G39: ='Financial Model'!#REF! -> #REF! | H39: ='Financial Model'!#REF! -> #REF! | ... U39: ='Financial Model'!#REF! -> #REF!
A40: ='Financial Model'!#REF! -> #REF! | B40: ='Financial Model'!#REF! -> #REF! | C40: ='Financial Model'!#REF! -> #REF! | D40: ='Financial Model'!#REF! -> #REF! | E40: ='Financial Model'!#REF! -> #REF! | F40: ='Financial Model'!#REF! -> #REF! | G40: ='Financial Model'!#REF! -> #REF! | H40: ='Financial Model'!#REF! -> #REF! | ... U40: ='Financial Model'!#REF! -> #REF!
A41: ='Financial Model'!#REF! -> #REF! | B41: ='Financial Model'!#REF! -> #REF! | C41: ='Financial Model'!#REF! -> #REF! | D41: ='Financial Model'!#REF! -> #REF! | E41: ='Financial Model'!#REF! -> #REF! | F41: ='Financial Model'!#REF! -> #REF! | G41: ='Financial Model'!#REF! -> #REF! | H41: ='Financial Model'!#REF! -> #REF! | ... U41: ='Financial Model'!#REF! -> #REF!
A42: ='Financial Model'!#REF! -> #REF! | B42: ='Financial Model'!#REF! -> #REF! | C42: ='Financial Model'!#REF! -> #REF! | D42: ='Financial Model'!#REF! -> #REF! | E42: ='Financial Model'!#REF! -> #REF! | F42: ='Financial Model'!#REF! -> #REF! | G42: ='Financial Model'!#REF! -> #REF! | H42: ='Financial Model'!#REF! -> #REF! | ... U42: ='Financial Model'!#REF! -> #REF!
A43: ='Financial Model'!#REF! -> #REF! | B43: ='Financial Model'!#REF! -> #REF! | C43: ='Financial Model'!#REF! -> #REF! | D43: ='Financial Model'!#REF! -> #REF! | E43: ='Financial Model'!#REF! -> #REF! | F43: ='Financial Model'!#REF! -> #REF! | G43: ='Financial Model'!#REF! -> #REF! | H43: ='Financial Model'!#REF! -> #REF! | ... U43: ='Financial Model'!#REF! -> #REF!
...

Sheet Profit and Loss
A1: Eqho, LLC
A2: Profit and Loss
A3: January 1 - December 12, 2024
B5: Jan 2024 | C5: Feb 2024 | D5: Mar 2024 | E5: Apr 2024 | F5: May 2024 | G5: Jun 2024 | H5: Jul 2024 | I5: Aug 2024 | J5: Sep 2024 | K5: Oct 2024 | L5: Nov 2024 | M5: Dec 1-12, 2024 | N5: Total
A6: Income
A7: Sales of Product Income | E7: =1646.38 -> 1646.38 | F7: =1453.45 -> 1453.45 | G7: =2209.52 -> 2209.52 | H7: =4351 -> 4351 | I7: =3776.29 -> 3776.29 | J7: =6766.28 -> 6766.28 | K7: =7713.07 -> 7713.07 | L7: =7637.72 -> 7637.72 | M7: =3269.63 -> 3269.63 | N7: =(((((((((((B7)+(C7))+(D7))+(E7))+(F7))+(G7))+(H7))+(I7))+(J7))+(K7))+(L7))+(M7) -> 38823.34
A8: Uncategorized Income | F8: =0.25 -> 0.25 | N8: =(((((((((((B8)+(C8))+(D8))+(E8))+(F8))+(G8))+(H8))+(I8))+(J8))+(K8))+(L8))+(M8) -> 0.25
A9: Total Income | B9: =(B7)+(B8) -> 0 | C9: =(C7)+(C8) -> 0 | D9: =(D7)+(D8) -> 0 | E9: =(E7)+(E8) -> 1646.38 | F9: =(F7)+(F8) -> 1453.7 | G9: =(G7)+(G8) -> 2209.52 | H9: =(H7)+(H8) -> 4351 | I9: =(I7)+(I8) -> 3776.29 | ... M9: =(M7)+(M8) -> 3269.63 | N9: =(((((((((((B9)+(C9))+(D9))+(E9))+(F9))+(G9))+(H9))+(I9))+(J9))+(K9))+(L9))+(M9) -> 38823.59 | P9: =SUM(B9:K9)/11 -> 2537.84
A10: Cost of Goods Sold | P10: =SUM(B10:K10)/11 -> 0
A11: Cloud Services | B11: =165.59 -> 165.59 | C11: =551.59 -> 551.59 | D11: =1590.99 -> 1590.99 | E11: =768.33 -> 768.33 | F11: =2692.83 -> 2692.83 | G11: =1236.67 -> 1236.67 | H11: =3428.37 -> 3428.37 | I11: =4061.47 -> 4061.47 | J11: =1212.47 -> 1212.47 | K11: =3162.95 -> 3162.95 | L11: =5485.06 -> 5485.06 | N11: =(((((((((((B11)+(C11))+(D11))+(E11))+(F11))+(G11))+(H11))+(I11))+(J11))+(K11))+(L11))+(M11) -> 24356.32 | P11: =SUM(B11:K11)/11 -> 1715.5691
A12: Software - COGS | B12: =38.51 -> 38.51 | C12: =47.71 -> 47.71 | D12: =307.55 -> 307.55 | E12: =1114.73 -> 1114.73 | F12: =4599.22 -> 4599.22 | G12: =2611.56 -> 2611.56 | H12: =3514.2 -> 3514.2 | I12: =1420.44 -> 1420.44 | J12: =2387.05 -> 2387.05 | K12: =2093.47 -> 2093.47 | L12: =52.61 -> 52.61 | N12: =(((((((((((B12)+(C12))+(D12))+(E12))+(F12))+(G12))+(H12))+(I12))+(J12))+(K12))+(L12))+(M12) -> 18187.05 | P12: =SUM(B12:K12)/11 -> 1648.5855
A13: Software - Tools | B13: =297.03 -> 297.03 | C13: =338.2 -> 338.2 | D13: =340.13 -> 340.13 | E13: =394.31 -> 394.31 | F13: =560.44 -> 560.44 | G13: =551.54 -> 551.54 | H13: =762.6 -> 762.6 | I13: =1791.57 -> 1791.57 | J13: =993.13 -> 993.13 | K13: =1085.62 -> 1085.62 | L13: =944.76 -> 944.76 | N13: =(((((((((((B13)+(C13))+(D13))+(E13))+(F13))+(G13))+(H13))+(I13))+(J13))+(K13))+(L13))+(M13) -> 8059.33 | P13: =SUM(B13:K13)/11 -> 646.77909
A14: Voice AI Provider | B14: =908.32 -> 908.32 | C14: =330 -> 330 | D14: =330 -> 330 | E14: =511.37 -> 511.37 | F14: =1387.79 -> 1387.79 | G14: =859.8 -> 859.8 | H14: =1599.82 -> 1599.82 | I14: =945.81 -> 945.81 | J14: =534.78 -> 534.78 | K14: =708.64 -> 708.64 | N14: =(((((((((((B14)+(C14))+(D14))+(E14))+(F14))+(G14))+(H14))+(I14))+(J14))+(K14))+(L14))+(M14) -> 8116.33 | P14: =SUM(B14:K14)/11 -> 737.84818
A15: Total Software - COGS | B15: =((B12)+(B13))+(B14) -> 1243.86 | C15: =((C12)+(C13))+(C14) -> 715.91 | D15: =((D12)+(D13))+(D14) -> 977.68 | E15: =((E12)+(E13))+(E14) -> 2020.41 | F15: =((F12)+(F13))+(F14) -> 6547.45 | G15: =((G12)+(G13))+(G14) -> 4022.9 | H15: =((H12)+(H13))+(H14) -> 5876.62 | I15: =((I12)+(I13))+(I14) -> 4157.82 | ... M15: =((M12)+(M13))+(M14) -> 0 | N15: =(((((((((((B15)+(C15))+(D15))+(E15))+(F15))+(G15))+(H15))+(I15))+(J15))+(K15))+(L15))+(M15) -> 34362.71 | P15: =SUM(B15:K15)/11 -> 3033.2127
A16: Telephony Carriers | B16: =151.26 -> 151.26 | C16: =75.86 -> 75.86 | D16: =301.96 -> 301.96 | E16: =309.86 -> 309.86 | F16: =2514.17 -> 2514.17 | G16: =1464.9 -> 1464.9 | H16: =2828.47 -> 2828.47 | I16: =1369.6 -> 1369.6 | J16: =1945.58 -> 1945.58 | K16: =2833.65 -> 2833.65 | L16: =1258.78 -> 1258.78 | N16: =(((((((((((B16)+(C16))+(D16))+(E16))+(F16))+(G16))+(H16))+(I16))+(J16))+(K16))+(L16))+(M16) -> 15054.09 | P16: =SUM(B16:K16)/11 -> 1254.1191
A17: Total Cost of Goods Sold | B17: =((B11)+(B15))+(B16) -> 1560.71 | C17: =((C11)+(C15))+(C16) -> 1343.36 | D17: =((D11)+(D15))+(D16) -> 2870.63 | E17: =((E11)+(E15))+(E16) -> 3098.6 | F17: =((F11)+(F15))+(F16) -> 11754.45 | G17: =((G11)+(G15))+(G16) -> 6724.47 | H17: =((H11)+(H15))+(H16) -> 12133.46 | I17: =((I11)+(I15))+(I16) -> 9588.89 | ... M17: =((M11)+(M15))+(M16) -> 0 | N17: =(((((((((((B17)+(C17))+(D17))+(E17))+(F17))+(G17))+(H17))+(I17))+(J17))+(K17))+(L17))+(M17) -> 73773.12 | P17: =SUM(B17:K17)/11 -> 6002.9009
A18: Gross Profit | B18: =(B9)-(B17) -> -1560.71 | C18: =(C9)-(C17) -> -1343.36 | D18: =(D9)-(D17) -> -2870.63 | E18: =(E9)-(E17) -> -1452.22 | F18: =(F9)-(F17) -> -10300.75 | G18: =(G9)-(G17) -> -4514.95 | H18: =(H9)-(H17) -> -7782.46 | I18: =(I9)-(I17) -> -5812.6 | ... M18: =(M9)-(M17) -> 3269.63 | N18: =(((((((((((B18)+(C18))+(D18))+(E18))+(F18))+(G18))+(H18))+(I18))+(J18))+(K18))+(L18))+(M18) -> -34949.53 | P18: =SUM(B18:K18)/11 -> -3465.0609
A19: Expenses | P19: =SUM(B19:K19)/11 -> 0
A20: Advertising & marketing | N20: =(((((((((((B20)+(C20))+(D20))+(E20))+(F20))+(G20))+(H20))+(I20))+(J20))+(K20))+(L20))+(M20) -> 0 | P20: =SUM(B20:K20)/11 -> 0
A21: Content Creation | B21: =2893.05 -> 2893.05 | N21: =(((((((((((B21)+(C21))+(D21))+(E21))+(F21))+(G21))+(H21))+(I21))+(J21))+(K21))+(L21))+(M21) -> 2893.05 | P21: =SUM(B21:K21)/11 -> 263.00455
A22: Listing fees | B22: =6.67 -> 6.67 | N22: =(((((((((((B22)+(C22))+(D22))+(E22))+(F22))+(G22))+(H22))+(I22))+(J22))+(K22))+(L22))+(M22) -> 6.67 | P22: =SUM(B22:K22)/11 -> 0.60636364
A23: Social media | C23: =347.32 -> 347.32 | D23: =1887.16 -> 1887.16 | E23: =1859 -> 1859 | F23: =1197.13 -> 1197.13 | G23: =1189.4 -> 1189.4 | H23: =1208.67 -> 1208.67 | I23: =230.38 -> 230.38 | J23: =41.12 -> 41.12 | K23: =848.44 -> 848.44 | L23: =856.68 -> 856.68 | N23: =(((((((((((B23)+(C23))+(D23))+(E23))+(F23))+(G23))+(H23))+(I23))+(J23))+(K23))+(L23))+(M23) -> 9665.3 | P23: =SUM(B23:K23)/11 -> 800.78364
A24: Software Marketing Tools | L24: =63.34 -> 63.34 | N24: =(((((((((((B24)+(C24))+(D24))+(E24))+(F24))+(G24))+(H24))+(I24))+(J24))+(K24))+(L24))+(M24) -> 63.34 | P24: =SUM(B24:K24)/11 -> 0
A25: Trade Shows | B25: =499.9 -> 499.9 | E25: =2331.68 -> 2331.68 | N25: =(((((((((((B25)+(C25))+(D25))+(E25))+(F25))+(G25))+(H25))+(I25))+(J25))+(K25))+(L25))+(M25) -> 2831.58 | P25: =SUM(B25:K25)/11 -> 257.41636
A26: Total Advertising & marketing | B26: =(((((B20)+(B21))+(B22))+(B23))+(B24))+(B25) -> 3399.62 | C26: =(((((C20)+(C21))+(C22))+(C23))+(C24))+(C25) -> 347.32 | D26: =(((((D20)+(D21))+(D22))+(D23))+(D24))+(D25) -> 1887.16 | E26: =(((((E20)+(E21))+(E22))+(E23))+(E24))+(E25) -> 4190.68 | F26: =(((((F20)+(F21))+(F22))+(F23))+(F24))+(F25) -> 1197.13 | G26: =(((((G20)+(G21))+(G22))+(G23))+(G24))+(G25) -> 1189.4 | H26: =(((((H20)+(H21))+(H22))+(H23))+(H24))+(H25) -> 1208.67 | I26: =(((((I20)+(I21))+(I22))+(I23))+(I24))+(I25) -> 230.38 | ... M26: =(((((M20)+(M21))+(M22))+(M23))+(M24))+(M25) -> 0 | N26: =(((((((((((B26)+(C26))+(D26))+(E26))+(F26))+(G26))+(H26))+(I26))+(J26))+(K26))+(L26))+(M26) -> 15459.94 | P26: =SUM(B26:K26)/11 -> 1321.8109
A27: Contract labor | B27: =51247.34 -> 51247.34 | C27: =46435.67 -> 46435.67 | D27: =67432.96 -> 67432.96 | E27: =50047.19 -> 50047.19 | F27: =68246.24 -> 68246.24 | G27: =81559.87 -> 81559.87 | H27: =84427.72 -> 84427.72 | I27: =78022.99 -> 78022.99 | J27: =29145.26 -> 29145.26 | K27: =34714.45 -> 34714.45 | L27: =41221.67 -> 41221.67 | M27: =5427.89 -> 5427.89 | N27: =(((((((((((B27)+(C27))+(D27))+(E27))+(F27))+(G27))+(H27))+(I27))+(J27))+(K27))+(L27))+(M27) -> 637929.25 | P27: =SUM(B27:K27)/11 -> 53752.699
A28: Upwork | E28: =789.23 -> 789.23 | F28: =-214.95 -> -214.95 | N28: =(((((((((((B28)+(C28))+(D28))+(E28))+(F28))+(G28))+(H28))+(I28))+(J28))+(K28))+(L28))+(M28) -> 574.28 | P28: =SUM(B28:K28)/11 -> 52.207273
A29: Total Contract labor | B29: =(B27)+(B28) -> 51247.34 | C29: =(C27)+(C28) -> 46435.67 | D29: =(D27)+(D28) -> 67432.96 | E29: =(E27)+(E28) -> 50836.42 | F29: =(F27)+(F28) -> 68031.29 | G29: =(G27)+(G28) -> 81559.87 | H29: =(H27)+(H28) -> 84427.72 | I29: =(I27)+(I28) -> 78022.99 | ... M29: =(M27)+(M28) -> 5427.89 | N29: =(((((((((((B29)+(C29))+(D29))+(E29))+(F29))+(G29))+(H29))+(I29))+(J29))+(K29))+(L29))+(M29) -> 638503.53 | P29: =SUM(B29:K29)/11 -> 53804.906
A30: General business expenses | N30: =(((((((((((B30)+(C30))+(D30))+(E30))+(F30))+(G30))+(H30))+(I30))+(J30))+(K30))+(L30))+(M30) -> 0 | P30: =SUM(B30:K30)/11 -> 0
A31: Bank fees & service charges | B31: =25 -> 25 | D31: =50 -> 50 | E31: =50 -> 50 | F31: =65 -> 65 | G31: =160 -> 160 | H31: =240 -> 240 | I31: =505 -> 505 | J31: =120 -> 120 | K31: =120 -> 120 | L31: =280 -> 280 | N31: =(((((((((((B31)+(C31))+(D31))+(E31))+(F31))+(G31))+(H31))+(I31))+(J31))+(K31))+(L31))+(M31) -> 1615 | P31: =SUM(B31:K31)/11 -> 121.36364
A32: Total General business expenses | B32: =(B30)+(B31) -> 25 | C32: =(C30)+(C31) -> 0 | D32: =(D30)+(D31) -> 50 | E32: =(E30)+(E31) -> 50 | F32: =(F30)+(F31) -> 65 | G32: =(G30)+(G31) -> 160 | H32: =(H30)+(H31) -> 240 | I32: =(I30)+(I31) -> 505 | ... M32: =(M30)+(M31) -> 0 | N32: =(((((((((((B32)+(C32))+(D32))+(E32))+(F32))+(G32))+(H32))+(I32))+(J32))+(K32))+(L32))+(M32) -> 1615 | P32: =SUM(B32:K32)/11 -> 121.36364
A33: Legal & accounting services | N33: =(((((((((((B33)+(C33))+(D33))+(E33))+(F33))+(G33))+(H33))+(I33))+(J33))+(K33))+(L33))+(M33) -> 0 | P33: =SUM(B33:K33)/11 -> 0
A34: Legal Fees | I34: =1800 -> 1800 | J34: =1800 -> 1800 | K34: =1800 -> 1800 | L34: =1800 -> 1800 | N34: =(((((((((((B34)+(C34))+(D34))+(E34))+(F34))+(G34))+(H34))+(I34))+(J34))+(K34))+(L34))+(M34) -> 7200 | P34: =SUM(B34:K34)/11 -> 490.90909
A35: Total Legal & accounting services | B35: =(B33)+(B34) -> 0 | C35: =(C33)+(C34) -> 0 | D35: =(D33)+(D34) -> 0 | E35: =(E33)+(E34) -> 0 | F35: =(F33)+(F34) -> 0 | G35: =(G33)+(G34) -> 0 | H35: =(H33)+(H34) -> 0 | I35: =(I33)+(I34) -> 1800 | ... M35: =(M33)+(M34) -> 0 | N35: =(((((((((((B35)+(C35))+(D35))+(E35))+(F35))+(G35))+(H35))+(I35))+(J35))+(K35))+(L35))+(M35) -> 7200 | P35: =SUM(B35:K35)/11 -> 490.90909
A36: Meals | B36: =160.43 -> 160.43 | E36: =34.47 -> 34.47 | G36: =14.39 -> 14.39 | H36: =26 -> 26 | I36: =14.7 -> 14.7 | J36: =47.54 -> 47.54 | N36: =(((((((((((B36)+(C36))+(D36))+(E36))+(F36))+(G36))+(H36))+(I36))+(J36))+(K36))+(L36))+(M36) -> 297.53 | P36: =SUM(B36:K36)/11 -> 27.048182
A37: Meals - Guzman | D37: =141.89 -> 141.89 | E37: =190.1 -> 190.1 | G37: =210.79 -> 210.79 | H37: =216.84 -> 216.84 | N37: =(((((((((((B37)+(C37))+(D37))+(E37))+(F37))+(G37))+(H37))+(I37))+(J37))+(K37))+(L37))+(M37) -> 759.62 | P37: =SUM(B37:K37)/11 -> 69.056364
A38: Meals with clients | B38: =1780.44 -> 1780.44 | C38: =280.94 -> 280.94 | D38: =219.79 -> 219.79 | E38: =145.66 -> 145.66 | F38: =169.56 -> 169.56 | G38: =106.8 -> 106.8 | H38: =387.56 -> 387.56 | I38: =453.29 -> 453.29 | J38: =389.7 -> 389.7 | K38: =499.47 -> 499.47 | L38: =245.5 -> 245.5 | M38: =23.94 -> 23.94 | N38: =(((((((((((B38)+(C38))+(D38))+(E38))+(F38))+(G38))+(H38))+(I38))+(J38))+(K38))+(L38))+(M38) -> 4702.65 | P38: =SUM(B38:K38)/11 -> 403.01909
A39: Travel meals | B39: =57.15 -> 57.15 | C39: =20.68 -> 20.68 | N39: =(((((((((((B39)+(C39))+(D39))+(E39))+(F39))+(G39))+(H39))+(I39))+(J39))+(K39))+(L39))+(M39) -> 77.83 | P39: =SUM(B39:K39)/11 -> 7.0754545
A40: Total Meals | B40: =(((B36)+(B37))+(B38))+(B39) -> 1998.02 | C40: =(((C36)+(C37))+(C38))+(C39) -> 301.62 | D40: =(((D36)+(D37))+(D38))+(D39) -> 361.68 | E40: =(((E36)+(E37))+(E38))+(E39) -> 370.23 | F40: =(((F36)+(F37))+(F38))+(F39) -> 169.56 | G40: =(((G36)+(G37))+(G38))+(G39) -> 331.98 | H40: =(((H36)+(H37))+(H38))+(H39) -> 630.4 | I40: =(((I36)+(I37))+(I38))+(I39) -> 467.99 | ... M40: =(((M36)+(M37))+(M38))+(M39) -> 23.94 | N40: =(((((((((((B40)+(C40))+(D40))+(E40))+(F40))+(G40))+(H40))+(I40))+(J40))+(K40))+(L40))+(M40) -> 5837.63 | P40: =SUM(B40:K40)/11 -> 506.19909
A41: Office expenses | N41: =(((((((((((B41)+(C41))+(D41))+(E41))+(F41))+(G41))+(H41))+(I41))+(J41))+(K41))+(L41))+(M41) -> 0 | P41: =SUM(B41:K41)/11 -> 0
...
